<?xml version="1.0" ?>
<!-- =================================================================================== -->
<!-- |    This document was autogenerated by xacro from /home/mfallon/rpg-navigation/code/src/anymal_ori/anymal_ori/urdf/anymal_ori.urdf.xacro | -->
<!-- |    EDITING THIS FILE BY HAND IS NOT RECOMMENDED                                 | -->
<!-- =================================================================================== -->
<!--Copyright (C) 2015 by Dario Bellicoso                                    -->
<!--bellicosodario@gmail.com                                                 -->
<!--                                                                         -->
<!--This program is free software; you can redistribute it and/or modify     -->
<!--it under the terms of the Lesser GNU General Public License as published -->
<!--by the Free Software Foundation; either version 3 of the License, or     -->
<!--(at your option) any later version.                                      -->
<!--                                                                         -->
<!--This program is distributed in the hope that it will be useful,          -->
<!--but WITHOUT ANY WARRANTY; without even the implied warranty of           -->
<!--MERCHANTABILITY or FITNESS FOR A PARTICULAR PURPOSE. See the             -->
<!--Lesser GNU General Public License for more details.                      -->
<!--                                                                         -->
<!--You should have received a copy of the Lesser GNU General Public License -->
<!--along with this program. If not, see <http://www.gnu.org/licenses/>.     -->
<!-- This file contains the description of the ANYmal robot. -->
<robot name="anymal" xmlns:xacro="http://www.ros.org/wiki/xacro">
  <material name="black">
    <color rgba="0.0 0.0 0.0 1.0"/>
  </material>
  <material name="blue">
    <color rgba="0.0 0.0 0.8 1.0"/>
  </material>
  <material name="green">
    <color rgba="0.0 0.8 0.0 1.0"/>
  </material>
  <material name="grey">
    <color rgba="0.2 0.2 0.2 1.0"/>
  </material>
  <material name="light_grey">
    <color rgba="0.4 0.4 0.4 1.0"/>
  </material>
  <material name="orange">
    <color rgba="1.0 0.423529411765 0.0392156862745 1.0"/>
  </material>
  <material name="brown">
    <color rgba="0.870588235294 0.811764705882 0.764705882353 1.0"/>
  </material>
  <material name="red">
    <color rgba="0.8 0.0 0.0 1.0"/>
  </material>
  <material name="white">
    <color rgba="1.0 1.0 1.0 1.0"/>
  </material>
  <gazebo>
    <plugin filename="libanymal_gazebo.so" name="gazebo_ros_control">
      <robotNamespace>anymal</robotNamespace>
      <!-- Currently unused -->
      <robotDescription>quadruped_description</robotDescription>
      <robotBaseLink>base</robotBaseLink>
      <statePublisherRate>400.0</statePublisherRate>
    </plugin>
  </gazebo>
  <!-- Material for the visual primitives -->
  <material name="anymal_material">
    <color rgba="0.76078431 0.73333333 0.72156863 1.0"/>
  </material>
  <!-- Xacro:Properties -->
  <!-- [m] -->
  <!-- Base link -->
  <link name="base">
    <visual>
      <origin rpy="0 0 0" xyz="0 0 0"/>
      <geometry>
        <mesh filename="package://anymal_description_ori/urdf/base/anymal_base_2.dae" scale="0.001 0.001     0.001"/>
      </geometry>
      <material name="anymal_material"/>
    </visual>
    <collision>
      <!-- Main Body -->
      <origin rpy="0 0 0" xyz="0 0 0.08"/>
      <geometry>
        <box size="0.531 0.232 0.26"/>
      </geometry>
    </collision>
    <collision>
      <!-- Belly plate front bump -->
      <origin rpy="0 0 0" xyz="0.2155 0.0 -0.09"/>
      <geometry>
        <box size="0.1 0.1 0.07"/>
      </geometry>
    </collision>
    <collision>
      <!-- Belly plate hind bump-->
      <origin rpy="0 0 0" xyz="-0.2155 0.0 -0.09"/>
      <geometry>
        <box size="0.1 0.1 0.07"/>
      </geometry>
    </collision>
  </link>
  <!-- Fixed joint to add dummy inertia link -->
  <joint name="base_to_base_inertia" type="fixed">
    <parent link="base"/>
    <child link="base_inertia"/>
    <origin rpy="0 0 0" xyz="0 0 0"/>
  </joint>
  <!-- Dummy inertia link, because KDL cannot have inertia on the base link -->
  <link name="base_inertia">
    <inertial>
      <origin rpy="0 0 0" xyz="0.022 -0.01 0.01"/>
      <mass value="18.29"/>
      <inertia ixx="0.268388530624" ixy="0.000775392455422" ixz="-0.0151848534451" iyy="0.884235660795" iyz="-0.000989297489507" izz="0.829158678306"/>
    </inertial>
  </link>
  <!-- Xacro:Properties -->
  <!-- [m] -->
  <!-- [Nm] -->
  <link name="LF_HIP">
    <visual>
      <origin rpy="0 0 0.0" xyz="0 0 0"/>
      <geometry>
        <mesh filename="package://anymal_description_ori/urdf/hip/anymal_hip_l.dae" scale="0.001 0.001     0.001"/>
      </geometry>
    </visual>
    <collision>
      <origin rpy="1.57079632679 0 0" xyz="0.0585 0.0315 0.0"/>
      <geometry>
        <cylinder length="0.08" radius="0.04"/>
      </geometry>
    </collision>
    <inertial>
      <origin rpy="0 0 0" xyz="0.0542 -0.0136 0.0"/>
      <mass value="1.1064"/>
      <inertia ixx="0.00123301508523" ixy="-6.4285329973e-05" ixz="6.9990104e-08" iyy="0.000993231183395" iyz="2.327401345e-06" izz="0.00142160349098"/>
    </inertial>
  </link>
  <!-- Hip joint -->
  <joint name="LF_HAA" type="revolute">
    <parent link="base"/>
    <child link="LF_HIP"/>
    <origin xyz="0.2629 0.115 0.0"/>
    <axis xyz="1 0 0"/>
    <limit effort="80" lower="-6.28" upper="6.28" velocity="15"/>
    <dynamics damping="0.0" friction="0.0"/>
  </joint>
  <!-- Xacro:Properties -->
  <!-- [m] -->
  <!-- [Nm] -->
  <link name="LF_THIGH">
    <visual>
      <origin rpy="0 0 0.0" xyz="0 0 0"/>
      <geometry>
        <mesh filename="package://anymal_description_ori/urdf/thigh/anymal_thigh_l.dae" scale="0.001 0.001     0.001"/>
      </geometry>
    </visual>
    <collision>
      <origin rpy="0.145 0 0" xyz="0 0.02 -0.1"/>
      <geometry>
        <cylinder length="0.2" radius="0.01"/>
      </geometry>
    </collision>
    <collision>
      <origin rpy="1.57079632679 0 0" xyz="0.0 0.07 -0.25"/>
      <geometry>
        <cylinder length="0.08" radius="0.04"/>
      </geometry>
    </collision>
    <inertial>
      <origin rpy="0 0 0" xyz="0.0008 0.0545 -0.1975"/>
      <mass value="1.51"/>
      <inertia ixx="0.0147571628275" ixy="-1.7996507882e-05" ixz="0.000205877679383" iyy="0.0144188925719" iyz="-0.00181291342366" izz="0.00178449075964"/>
    </inertial>
  </link>
  <!-- Thigh joint -->
  <joint name="LF_HFE" type="revolute">
    <parent link="LF_HIP"/>
    <child link="LF_THIGH"/>
    <origin xyz="0.0585                    0.0315                    0.0"/>
    <axis xyz="0 1 0"/>
    <limit effort="80" lower="-6.28" upper="6.28" velocity="15"/>
    <dynamics damping="0.0" friction="0.0"/>
  </joint>
  <!-- Xacro:Properties -->
  <!-- [m] -->
  <!-- [Nm] -->
  <link name="LF_SHANK">
    <visual>
      <origin rpy="0 0 0.0" xyz="0 0 0"/>
      <geometry>
        <mesh filename="package://anymal_description_ori/urdf/shank/anymal_shank_2_l.dae" scale="0.001 0.001     0.001"/>
      </geometry>
    </visual>
    <collision>
      <origin rpy="0 -0.9 -0.2" xyz="0.04 -0.02 -0.04"/>
      <geometry>
        <cylinder length="0.13" radius="0.015"/>
      </geometry>
    </collision>
    <collision>
      <origin rpy="-0.0 0.34 0" xyz="0.06 -0.03 -0.18"/>
      <geometry>
        <cylinder length="0.19" radius="0.015"/>
      </geometry>
    </collision>
    <inertial>
      <origin rpy="0 0 0" xyz="0.016355414056 -0.00562219106 -0.064350437219"/>
      <mass value="0.318"/>
      <inertia ixx="0.0037693717909" ixy="-7.7334500762e-05" ixz="-0.000152069372983" iyy="0.00400446467635" iyz="-0.0003218356083" izz="0.000418471691904"/>
    </inertial>
  </link>
  <!-- Shank joint -->
  <joint name="LF_KFE" type="revolute">
    <parent link="LF_THIGH"/>
    <child link="LF_SHANK"/>
    <origin xyz="0.0 0.111 -0.25"/>
    <axis xyz="0 1 0"/>
    <limit effort="80" lower="-6.28" upper="6.28" velocity="15"/>
    <dynamics damping="0.0" friction="0.0"/>
  </joint>
  <!-- Foot mount link -->
  <link name="LF_FOOT_MOUNT"/>
  <!-- Foot mount joint / ankle -->
  <joint name="LF_ANKLE_JOINT" type="fixed">
    <parent link="LF_SHANK"/>
    <child link="LF_FOOT_MOUNT"/>
    <origin rpy="0.323 0.549 0" xyz="0.0 -0.016 -0.31"/>
  </joint>
  <!-- Xacro:Properties -->
  <!-- [m] -->
  <link name="LF_FOOT_SENSOR">
    <visual>
      <origin rpy="0 0 0" xyz="0 0 0"/>
      <geometry>
        <mesh filename="package://anymal_description_ori/urdf/foot/anymal_foot_2.dae" scale="0.001 0.001     0.001"/>
      </geometry>
    </visual>
    <collision>
      <origin rpy="0 0 0" xyz="0.0 0.0 -0.0385"/>
      <geometry>
        <sphere radius="0.02"/>
      </geometry>
    </collision>
    <inertial>
      <origin rpy="0 0 0" xyz="-5.552058e-06 7.1133124e-05 -0.021388647779"/>
      <mass value="0.1922685"/>
      <inertia ixx="8.3086410294e-05" ixy="4.16901601e-07" ixz="3.99054799e-07" iyy="8.2860209667e-05" iyz="-3.45712252e-07" izz="8.1948124086e-05"/>
    </inertial>
  </link>
  <!-- Foot sensor joint -->
  <joint name="LF_MOUNT_TO_SENSOR" type="fixed">
    <parent link="LF_FOOT_MOUNT"/>
    <child link="LF_FOOT_SENSOR"/>
    <origin rpy="0 0 0" xyz="0 0 0"/>
  </joint>
  <!-- Gazebo customization -->
  <gazebo reference="LF_FOOT_SENSOR">
    <kp>1000000.0</kp>
    <kd>100.0</kd>
    <mu1>0.8</mu1>
    <mu2>0.8</mu2>
  </gazebo>
  <gazebo reference="LF_MOUNT_TO_SENSOR"/>
  <!-- Foot link -->
  <link name="LF_FOOT">
    </link>
  <!-- Foot joint -->
  <joint name="LF_SENSOR_TO_FOOT" type="fixed">
    <parent link="LF_FOOT_SENSOR"/>
    <child link="LF_FOOT"/>
    <origin rpy="0 0 0" xyz="0.0 0.0 -0.0385"/>
  </joint>
  <!-- Xacro:Properties -->
  <!-- [m] -->
  <!-- [Nm] -->
  <link name="RF_HIP">
    <visual>
      <origin rpy="0 0 0.0" xyz="0 0 0"/>
      <geometry>
        <mesh filename="package://anymal_description_ori/urdf/hip/anymal_hip_r.dae" scale="0.001 0.001     0.001"/>
      </geometry>
    </visual>
    <collision>
      <origin rpy="1.57079632679 0 0" xyz="0.0585 -0.0315 0.0"/>
      <geometry>
        <cylinder length="0.08" radius="0.04"/>
      </geometry>
    </collision>
    <inertial>
      <origin rpy="0 0 0" xyz="0.0542 0.0136 0.0"/>
      <mass value="1.1064"/>
      <inertia ixx="0.00123301508523" ixy="6.4285329973e-05" ixz="6.9990104e-08" iyy="0.000993231183395" iyz="-2.327401345e-06" izz="0.00142160349098"/>
    </inertial>
  </link>
  <!-- Hip joint -->
  <joint name="RF_HAA" type="revolute">
    <parent link="base"/>
    <child link="RF_HIP"/>
    <origin xyz="0.2629 -0.115 0.0"/>
    <axis xyz="1 0 0"/>
    <limit effort="80" lower="-6.28" upper="6.28" velocity="15"/>
    <dynamics damping="0.0" friction="0.0"/>
  </joint>
  <!-- Xacro:Properties -->
  <!-- [m] -->
  <!-- [Nm] -->
  <link name="RF_THIGH">
    <visual>
      <origin rpy="0 0 0.0" xyz="0 0 0"/>
      <geometry>
        <mesh filename="package://anymal_description_ori/urdf/thigh/anymal_thigh_r.dae" scale="0.001 0.001     0.001"/>
      </geometry>
    </visual>
    <collision>
      <origin rpy="-0.145 0 0" xyz="0 -0.02 -0.1"/>
      <geometry>
        <cylinder length="0.2" radius="0.01"/>
      </geometry>
    </collision>
    <collision>
      <origin rpy="1.57079632679 0 0" xyz="0.0 -0.07 -0.25"/>
      <geometry>
        <cylinder length="0.08" radius="0.04"/>
      </geometry>
    </collision>
    <inertial>
      <origin rpy="0 0 0" xyz="0.0008 -0.0545 -0.1975"/>
      <mass value="1.51"/>
      <inertia ixx="0.0147571628275" ixy="1.7996507882e-05" ixz="0.000205877679383" iyy="0.0144188925719" iyz="0.00181291342366" izz="0.00178449075964"/>
    </inertial>
  </link>
  <!-- Thigh joint -->
  <joint name="RF_HFE" type="revolute">
    <parent link="RF_HIP"/>
    <child link="RF_THIGH"/>
    <origin xyz="0.0585                    -0.0315                    0.0"/>
    <axis xyz="0 1 0"/>
    <limit effort="80" lower="-6.28" upper="6.28" velocity="15"/>
    <dynamics damping="0.0" friction="0.0"/>
  </joint>
  <!-- Xacro:Properties -->
  <!-- [m] -->
  <!-- [Nm] -->
  <link name="RF_SHANK">
    <visual>
      <origin rpy="0 0 0.0" xyz="0 0 0"/>
      <geometry>
        <mesh filename="package://anymal_description_ori/urdf/shank/anymal_shank_2_r.dae" scale="0.001 0.001     0.001"/>
      </geometry>
    </visual>
    <collision>
      <origin rpy="0 -0.9 0.2" xyz="0.04 0.02 -0.04"/>
      <geometry>
        <cylinder length="0.13" radius="0.015"/>
      </geometry>
    </collision>
    <collision>
      <origin rpy="0.0 0.34 0" xyz="0.06 0.03 -0.18"/>
      <geometry>
        <cylinder length="0.19" radius="0.015"/>
      </geometry>
    </collision>
    <inertial>
      <origin rpy="0 0 0" xyz="0.016355414056 0.00562219106 -0.064350437219"/>
      <mass value="0.318"/>
      <inertia ixx="0.0037693717909" ixy="7.7334500762e-05" ixz="-0.000152069372983" iyy="0.00400446467635" iyz="0.0003218356083" izz="0.000418471691904"/>
    </inertial>
  </link>
  <!-- Shank joint -->
  <joint name="RF_KFE" type="revolute">
    <parent link="RF_THIGH"/>
    <child link="RF_SHANK"/>
    <origin xyz="0.0 -0.111 -0.25"/>
    <axis xyz="0 1 0"/>
    <limit effort="80" lower="-6.28" upper="6.28" velocity="15"/>
    <dynamics damping="0.0" friction="0.0"/>
  </joint>
  <!-- Foot mount link -->
  <link name="RF_FOOT_MOUNT"/>
  <!-- Foot mount joint / ankle -->
  <joint name="RF_ANKLE_JOINT" type="fixed">
    <parent link="RF_SHANK"/>
    <child link="RF_FOOT_MOUNT"/>
    <origin rpy="-0.323 0.549 0" xyz="0.0 0.016 -0.31"/>
  </joint>
  <!-- Xacro:Properties -->
  <!-- [m] -->
  <link name="RF_FOOT_SENSOR">
    <visual>
      <origin rpy="0 0 0" xyz="0 0 0"/>
      <geometry>
        <mesh filename="package://anymal_description_ori/urdf/foot/anymal_foot_2.dae" scale="0.001 0.001     0.001"/>
      </geometry>
    </visual>
    <collision>
      <origin rpy="0 0 0" xyz="0.0 0.0 -0.0385"/>
      <geometry>
        <sphere radius="0.02"/>
      </geometry>
    </collision>
    <inertial>
      <origin rpy="0 0 0" xyz="-5.552058e-06 -7.1133124e-05 -0.021388647779"/>
      <mass value="0.1922685"/>
      <inertia ixx="8.3086410294e-05" ixy="-4.16901601e-07" ixz="3.99054799e-07" iyy="8.2860209667e-05" iyz="3.45712252e-07" izz="8.1948124086e-05"/>
    </inertial>
  </link>
  <!-- Foot sensor joint -->
  <joint name="RF_MOUNT_TO_SENSOR" type="fixed">
    <parent link="RF_FOOT_MOUNT"/>
    <child link="RF_FOOT_SENSOR"/>
    <origin rpy="0 0 0" xyz="0 0 0"/>
  </joint>
  <!-- Gazebo customization -->
  <gazebo reference="RF_FOOT_SENSOR">
    <kp>1000000.0</kp>
    <kd>100.0</kd>
    <mu1>0.8</mu1>
    <mu2>0.8</mu2>
  </gazebo>
  <gazebo reference="RF_MOUNT_TO_SENSOR"/>
  <!-- Foot link -->
  <link name="RF_FOOT">
    </link>
  <!-- Foot joint -->
  <joint name="RF_SENSOR_TO_FOOT" type="fixed">
    <parent link="RF_FOOT_SENSOR"/>
    <child link="RF_FOOT"/>
    <origin rpy="0 0 0" xyz="0.0 0.0 -0.0385"/>
  </joint>
  <!-- Xacro:Properties -->
  <!-- [m] -->
  <!-- [Nm] -->
  <link name="LH_HIP">
    <visual>
      <origin rpy="0 0 -3.14159265359" xyz="0 0 0"/>
      <geometry>
        <mesh filename="package://anymal_description_ori/urdf/hip/anymal_hip_r.dae" scale="0.001 0.001     0.001"/>
      </geometry>
    </visual>
    <collision>
      <origin rpy="-1.57079632679 0 0" xyz="-0.0585 0.0315 0.0"/>
      <geometry>
        <cylinder length="0.08" radius="0.04"/>
      </geometry>
    </collision>
    <inertial>
      <origin rpy="0 0 0" xyz="-0.0542 -0.0136 0.0"/>
      <mass value="1.1064"/>
      <inertia ixx="0.00123301508523" ixy="6.4285329973e-05" ixz="-6.9990104e-08" iyy="0.000993231183395" iyz="2.327401345e-06" izz="0.00142160349098"/>
    </inertial>
  </link>
  <!-- Hip joint -->
  <joint name="LH_HAA" type="revolute">
    <parent link="base"/>
    <child link="LH_HIP"/>
    <origin xyz="-0.2629 0.115 0.0"/>
    <axis xyz="1 0 0"/>
    <limit effort="80" lower="-6.28" upper="6.28" velocity="15"/>
    <dynamics damping="0.0" friction="0.0"/>
  </joint>
  <!-- Xacro:Properties -->
  <!-- [m] -->
  <!-- [Nm] -->
  <link name="LH_THIGH">
    <visual>
      <origin rpy="0 0 -3.14159265359" xyz="0 0 0"/>
      <geometry>
        <mesh filename="package://anymal_description_ori/urdf/thigh/anymal_thigh_r.dae" scale="0.001 0.001     0.001"/>
      </geometry>
    </visual>
    <collision>
      <origin rpy="0.145 0 0" xyz="0 0.02 -0.1"/>
      <geometry>
        <cylinder length="0.2" radius="0.01"/>
      </geometry>
    </collision>
    <collision>
      <origin rpy="1.57079632679 0 0" xyz="0.0 0.07 -0.25"/>
      <geometry>
        <cylinder length="0.08" radius="0.04"/>
      </geometry>
    </collision>
    <inertial>
      <origin rpy="0 0 0" xyz="-0.0008 0.0545 -0.1975"/>
      <mass value="1.51"/>
      <inertia ixx="0.0147571628275" ixy="1.7996507882e-05" ixz="-0.000205877679383" iyy="0.0144188925719" iyz="-0.00181291342366" izz="0.00178449075964"/>
    </inertial>
  </link>
  <!-- Thigh joint -->
  <joint name="LH_HFE" type="revolute">
    <parent link="LH_HIP"/>
    <child link="LH_THIGH"/>
    <origin xyz="-0.0585                    0.0315                    0.0"/>
    <axis xyz="0 1 0"/>
    <limit effort="80" lower="-6.28" upper="6.28" velocity="15"/>
    <dynamics damping="0.0" friction="0.0"/>
  </joint>
  <!-- Xacro:Properties -->
  <!-- [m] -->
  <!-- [Nm] -->
  <link name="LH_SHANK">
    <visual>
      <origin rpy="0 0 -3.14159265359" xyz="0 0 0"/>
      <geometry>
        <mesh filename="package://anymal_description_ori/urdf/shank/anymal_shank_2_r.dae" scale="0.001 0.001     0.001"/>
      </geometry>
    </visual>
    <collision>
      <origin rpy="0 0.9 0.2" xyz="-0.04 -0.02 -0.04"/>
      <geometry>
        <cylinder length="0.13" radius="0.015"/>
      </geometry>
    </collision>
    <collision>
      <origin rpy="-0.0 -0.34 0" xyz="-0.06 -0.03 -0.18"/>
      <geometry>
        <cylinder length="0.19" radius="0.015"/>
      </geometry>
    </collision>
    <inertial>
      <origin rpy="0 0 0" xyz="-0.016355414056 -0.00562219106 -0.064350437219"/>
      <mass value="0.318"/>
      <inertia ixx="0.0037693717909" ixy="7.7334500762e-05" ixz="0.000152069372983" iyy="0.00400446467635" iyz="-0.0003218356083" izz="0.000418471691904"/>
    </inertial>
  </link>
  <!-- Shank joint -->
  <joint name="LH_KFE" type="revolute">
    <parent link="LH_THIGH"/>
    <child link="LH_SHANK"/>
    <origin xyz="-0.0 0.111 -0.25"/>
    <axis xyz="0 1 0"/>
    <limit effort="80" lower="-6.28" upper="6.28" velocity="15"/>
    <dynamics damping="0.0" friction="0.0"/>
  </joint>
  <!-- Foot mount link -->
  <link name="LH_FOOT_MOUNT"/>
  <!-- Foot mount joint / ankle -->
  <joint name="LH_ANKLE_JOINT" type="fixed">
    <parent link="LH_SHANK"/>
    <child link="LH_FOOT_MOUNT"/>
    <origin rpy="0.323 -0.549 0" xyz="-0.0 -0.016 -0.31"/>
  </joint>
  <!-- Xacro:Properties -->
  <!-- [m] -->
  <link name="LH_FOOT_SENSOR">
    <visual>
      <origin rpy="0 0 0" xyz="0 0 0"/>
      <geometry>
        <mesh filename="package://anymal_description_ori/urdf/foot/anymal_foot_2.dae" scale="0.001 0.001     0.001"/>
      </geometry>
    </visual>
    <collision>
      <origin rpy="0 0 0" xyz="0.0 0.0 -0.0385"/>
      <geometry>
        <sphere radius="0.02"/>
      </geometry>
    </collision>
    <inertial>
      <origin rpy="0 0 0" xyz="5.552058e-06 7.1133124e-05 -0.021388647779"/>
      <mass value="0.1922685"/>
      <inertia ixx="8.3086410294e-05" ixy="-4.16901601e-07" ixz="-3.99054799e-07" iyy="8.2860209667e-05" iyz="-3.45712252e-07" izz="8.1948124086e-05"/>
    </inertial>
  </link>
  <!-- Foot sensor joint -->
  <joint name="LH_MOUNT_TO_SENSOR" type="fixed">
    <parent link="LH_FOOT_MOUNT"/>
    <child link="LH_FOOT_SENSOR"/>
    <origin rpy="0 0 0" xyz="0 0 0"/>
  </joint>
  <!-- Gazebo customization -->
  <gazebo reference="LH_FOOT_SENSOR">
    <kp>1000000.0</kp>
    <kd>100.0</kd>
    <mu1>0.8</mu1>
    <mu2>0.8</mu2>
  </gazebo>
  <gazebo reference="LH_MOUNT_TO_SENSOR"/>
  <!-- Foot link -->
  <link name="LH_FOOT">
    </link>
  <!-- Foot joint -->
  <joint name="LH_SENSOR_TO_FOOT" type="fixed">
    <parent link="LH_FOOT_SENSOR"/>
    <child link="LH_FOOT"/>
    <origin rpy="0 0 0" xyz="0.0 0.0 -0.0385"/>
  </joint>
  <!-- Xacro:Properties -->
  <!-- [m] -->
  <!-- [Nm] -->
  <link name="RH_HIP">
    <visual>
      <origin rpy="0 0 -3.14159265359" xyz="0 0 0"/>
      <geometry>
        <mesh filename="package://anymal_description_ori/urdf/hip/anymal_hip_l.dae" scale="0.001 0.001     0.001"/>
      </geometry>
    </visual>
    <collision>
      <origin rpy="-1.57079632679 0 0" xyz="-0.0585 -0.0315 0.0"/>
      <geometry>
        <cylinder length="0.08" radius="0.04"/>
      </geometry>
    </collision>
    <inertial>
      <origin rpy="0 0 0" xyz="-0.0542 0.0136 0.0"/>
      <mass value="1.1064"/>
      <inertia ixx="0.00123301508523" ixy="-6.4285329973e-05" ixz="-6.9990104e-08" iyy="0.000993231183395" iyz="-2.327401345e-06" izz="0.00142160349098"/>
    </inertial>
  </link>
  <!-- Hip joint -->
  <joint name="RH_HAA" type="revolute">
    <parent link="base"/>
    <child link="RH_HIP"/>
    <origin xyz="-0.2629 -0.115 0.0"/>
    <axis xyz="1 0 0"/>
    <limit effort="80" lower="-6.28" upper="6.28" velocity="15"/>
    <dynamics damping="0.0" friction="0.0"/>
  </joint>
  <!-- Xacro:Properties -->
  <!-- [m] -->
  <!-- [Nm] -->
  <link name="RH_THIGH">
    <visual>
      <origin rpy="0 0 -3.14159265359" xyz="0 0 0"/>
      <geometry>
        <mesh filename="package://anymal_description_ori/urdf/thigh/anymal_thigh_l.dae" scale="0.001 0.001     0.001"/>
      </geometry>
    </visual>
    <collision>
      <origin rpy="-0.145 0 0" xyz="0 -0.02 -0.1"/>
      <geometry>
        <cylinder length="0.2" radius="0.01"/>
      </geometry>
    </collision>
    <collision>
      <origin rpy="1.57079632679 0 0" xyz="0.0 -0.07 -0.25"/>
      <geometry>
        <cylinder length="0.08" radius="0.04"/>
      </geometry>
    </collision>
    <inertial>
      <origin rpy="0 0 0" xyz="-0.0008 -0.0545 -0.1975"/>
      <mass value="1.51"/>
      <inertia ixx="0.0147571628275" ixy="-1.7996507882e-05" ixz="-0.000205877679383" iyy="0.0144188925719" iyz="0.00181291342366" izz="0.00178449075964"/>
    </inertial>
  </link>
  <!-- Thigh joint -->
  <joint name="RH_HFE" type="revolute">
    <parent link="RH_HIP"/>
    <child link="RH_THIGH"/>
    <origin xyz="-0.0585                    -0.0315                    0.0"/>
    <axis xyz="0 1 0"/>
    <limit effort="80" lower="-6.28" upper="6.28" velocity="15"/>
    <dynamics damping="0.0" friction="0.0"/>
  </joint>
  <!-- Xacro:Properties -->
  <!-- [m] -->
  <!-- [Nm] -->
  <link name="RH_SHANK">
    <visual>
      <origin rpy="0 0 -3.14159265359" xyz="0 0 0"/>
      <geometry>
        <mesh filename="package://anymal_description_ori/urdf/shank/anymal_shank_2_l.dae" scale="0.001 0.001     0.001"/>
      </geometry>
    </visual>
    <collision>
      <origin rpy="0 0.9 -0.2" xyz="-0.04 0.02 -0.04"/>
      <geometry>
        <cylinder length="0.13" radius="0.015"/>
      </geometry>
    </collision>
    <collision>
      <origin rpy="0.0 -0.34 0" xyz="-0.06 0.03 -0.18"/>
      <geometry>
        <cylinder length="0.19" radius="0.015"/>
      </geometry>
    </collision>
    <inertial>
      <origin rpy="0 0 0" xyz="-0.016355414056 0.00562219106 -0.064350437219"/>
      <mass value="0.318"/>
      <inertia ixx="0.0037693717909" ixy="-7.7334500762e-05" ixz="0.000152069372983" iyy="0.00400446467635" iyz="0.0003218356083" izz="0.000418471691904"/>
    </inertial>
  </link>
  <!-- Shank joint -->
  <joint name="RH_KFE" type="revolute">
    <parent link="RH_THIGH"/>
    <child link="RH_SHANK"/>
    <origin xyz="-0.0 -0.111 -0.25"/>
    <axis xyz="0 1 0"/>
    <limit effort="80" lower="-6.28" upper="6.28" velocity="15"/>
    <dynamics damping="0.0" friction="0.0"/>
  </joint>
  <!-- Foot mount link -->
  <link name="RH_FOOT_MOUNT"/>
  <!-- Foot mount joint / ankle -->
  <joint name="RH_ANKLE_JOINT" type="fixed">
    <parent link="RH_SHANK"/>
    <child link="RH_FOOT_MOUNT"/>
    <origin rpy="-0.323 -0.549 0" xyz="-0.0 0.016 -0.31"/>
  </joint>
  <!-- Xacro:Properties -->
  <!-- [m] -->
  <link name="RH_FOOT_SENSOR">
    <visual>
      <origin rpy="0 0 0" xyz="0 0 0"/>
      <geometry>
        <mesh filename="package://anymal_description_ori/urdf/foot/anymal_foot_2.dae" scale="0.001 0.001     0.001"/>
      </geometry>
    </visual>
    <collision>
      <origin rpy="0 0 0" xyz="0.0 0.0 -0.0385"/>
      <geometry>
        <sphere radius="0.02"/>
      </geometry>
    </collision>
    <inertial>
      <origin rpy="0 0 0" xyz="5.552058e-06 -7.1133124e-05 -0.021388647779"/>
      <mass value="0.1922685"/>
      <inertia ixx="8.3086410294e-05" ixy="4.16901601e-07" ixz="-3.99054799e-07" iyy="8.2860209667e-05" iyz="3.45712252e-07" izz="8.1948124086e-05"/>
    </inertial>
  </link>
  <!-- Foot sensor joint -->
  <joint name="RH_MOUNT_TO_SENSOR" type="fixed">
    <parent link="RH_FOOT_MOUNT"/>
    <child link="RH_FOOT_SENSOR"/>
    <origin rpy="0 0 0" xyz="0 0 0"/>
  </joint>
  <!-- Gazebo customization -->
  <gazebo reference="RH_FOOT_SENSOR">
    <kp>1000000.0</kp>
    <kd>100.0</kd>
    <mu1>0.8</mu1>
    <mu2>0.8</mu2>
  </gazebo>
  <gazebo reference="RH_MOUNT_TO_SENSOR"/>
  <!-- Foot link -->
  <link name="RH_FOOT">
    </link>
  <!-- Foot joint -->
  <joint name="RH_SENSOR_TO_FOOT" type="fixed">
    <parent link="RH_FOOT_SENSOR"/>
    <child link="RH_FOOT"/>
    <origin rpy="0 0 0" xyz="0.0 0.0 -0.0385"/>
  </joint>
  <link name="imu_link">
    <visual>
      <origin rpy="0 0 0" xyz="0 0 0.011"/>
      <geometry>
        <box size="0.058 0.058 0.022"/>
      </geometry>
      <material name="orange"/>
    </visual>
    <collision>
      <origin rpy="0 0 0" xyz="0 0 0.011"/>
      <geometry>
        <box size="0.058 0.058 0.022"/>
      </geometry>
    </collision>
    <inertial>
      <mass value="0.05"/>
      <origin xyz="0 0 0"/>
      <inertia ixx="1.60333333333e-05" ixy="0.0" ixz="0.0" iyy="2.80333333333e-05" iyz="0.0" izz="1.60333333333e-05"/>
    </inertial>
  </link>
  <joint name="imu_joint" type="fixed">
    <parent link="base"/>
    <child link="imu_link"/>
    <origin rpy="3.14159265359 0 0" xyz="0.0245 -0.04255 0.1857"/>
  </joint>
  <gazebo reference="imu_link">
    <material>Gazebo/Orange</material>
    <mu1>0.8</mu1>
    <mu2>0.8</mu2>
  </gazebo>
  <gazebo reference="imu_joint">
      </gazebo>
  <gazebo>
    <plugin filename="libhector_gazebo_ros_imu.so" name="imu_plugin">
      <robotNamespace>sensors</robotNamespace>
      <bodyName>imu_link</bodyName>
      <frameId>/imu_link</frameId>
      <topicName>imu</topicName>
      <biasTopicName>imu/bias</biasTopicName>
      <serviceName>imu/calibrate</serviceName>
      <updateRate>400</updateRate>
      <!-- See https://www.xsens.com/wp-content/uploads/2013/11/mti-leaflet.pdf for the complete IMU specs-->
      <accelOffset>0 0 0</accelOffset>
      <accelDrift>0.5 0.5 0.5</accelDrift>
      <accelDriftFrequency>0 0 0</accelDriftFrequency>
      <accelGaussianNoise>0.35 0.35 0.3</accelGaussianNoise>
      <accelScaleError>1 1 1</accelScaleError>
      <rateOffset>0 0 0</rateOffset>
      <rateDrift>0.1 0.1 0.1</rateDrift>
      <rateDriftFrequency>0 0 0</rateDriftFrequency>
      <rateGaussianNoise>0.05 0.05 0.015</rateGaussianNoise>
      <rateScaleError>1 1 1</rateScaleError>
      <yawOffset>0</yawOffset>
      <yawDrift>0.1</yawDrift>
      <yawDriftFrequency>0</yawDriftFrequency>
      <yawGaussianNoise>0.05</yawGaussianNoise>
      <yawScaleError>1</yawScaleError>
      <xyzOffsets>0 0 0</xyzOffsets>
      <rpyOffsets>0 0 0</rpyOffsets>
    </plugin>
  </gazebo>
  <joint name="base_to_actuated_lidar_front_mass" type="fixed">
    <origin rpy="0.0 0.0 0.0" xyz="0.0 0.0 0.0"/>
    <parent link="base"/>
    <child link="actuated_lidar_front_mass"/>
  </joint>
  <link name="actuated_lidar_front_mass">
    <inertial>
      <origin rpy="0 0 0" xyz="0.292841755952 0.001047900228 0.141427870709"/>
      <mass value="1.392418888"/>
      <inertia ixx="0.002305684069948" ixy="-0.000086948644451" ixz="0.000921858442372" iyy="0.006893867805815" iyz="0.000017735314243" izz="0.006221132462993"/>
    </inertial>
  </link>
  <joint name="base_to_actuated_lidar_front_dynamixel_axis_aligned" type="fixed">
    <origin rpy="1.57079632679 0.0 1.57079632679" xyz="0.2 0.0 0.1415"/>
    <parent link="base"/>
    <child link="actuated_lidar_front_dynamixel_axis_aligned"/>
  </joint>
  <link name="actuated_lidar_front_dynamixel_axis_aligned">
    <visual>
      <origin rpy="0 0 0" xyz="0 0 0"/>
      <geometry>
        <mesh filename="package://actuated_lidar_description_ori/mesh/case_fix.dae" scale=".001 .001 .001"/>
      </geometry>
    </visual>
    <visual>
      <origin rpy="0 0 0" xyz="0 0 0"/>
      <geometry>
        <mesh filename="package://dynamixel_description/mesh/MX64.stl" scale=".001 .001 .001"/>
      </geometry>
      <material name="black">
        <color rgba="0.1 0.1 0.1 1"/>
      </material>
    </visual>
    <inertial>
      <origin rpy="0 0 0" xyz="0 0 0"/>
      <!-- Set the inertial parameters to neglectable values: these effects will be considered on a different rigid body -->
      <mass value="0.001"/>
      <inertia ixx="0.00001" ixy="0.0" ixz="0.0" iyy="0.00001" iyz="0.0" izz="0.00001"/>
    </inertial>
  </link>
  <joint name="actuated_lidar_front_dynamixel_axis_aligned_to_dynamixel" type="fixed">
    <origin rpy="0.0 0.0 0.0" xyz="0.0 0.0 0.0"/>
    <parent link="actuated_lidar_front_dynamixel_axis_aligned"/>
    <child link="actuated_lidar_front_dynamixel"/>
  </joint>
  <link name="actuated_lidar_front_dynamixel">
    <inertial>
      <origin rpy="0 0 0" xyz="0 0 0"/>
      <!-- Set the inertial parameters to neglectable values: these effects will be considered on a different rigid body -->
      <mass value="0.001"/>
      <inertia ixx="0.00001" ixy="0.0" ixz="0.0" iyy="0.00001" iyz="0.0" izz="0.00001"/>
      <!--<mass value="0.13"/>-->
      <!--<inertia ixx="0.000027961" ixy="0.0" ixz="0.0" iyy="0.000052184" iyz="0.0" izz="0.000043723"/>-->
    </inertial>
  </link>
  <joint name="actuated_lidar_front_dynamixel" type="continuous">
    <physics>
      <provide_feedback>true</provide_feedback>
    </physics>
    <parent link="actuated_lidar_front_dynamixel"/>
    <child link="actuated_lidar_front_dynamixel_servo"/>
    <limit effort="10" velocity="10"/>
    <origin rpy="0 0 0" xyz="0 0 0"/>
    <axis xyz="0 0 -1"/>
    <dynamics damping="0.0"/>
  </joint>
  <link name="actuated_lidar_front_dynamixel_servo"/>
  <joint name="actuated_lidar_front_dynamixel_servo_to_hokuyo_axis_aligned" type="fixed">
    <origin rpy="-1.57079632679 -1.57079632679 0" xyz="0 0 0.1515"/>
    <parent link="actuated_lidar_front_dynamixel_servo"/>
    <child link="actuated_lidar_front_hokuyo_axis_aligned"/>
  </joint>
  <link name="actuated_lidar_front_hokuyo_axis_aligned"/>
  <joint name="actuated_lidar_front_hokuyo_axis_aligned_to_hokuyo" type="fixed">
    <origin rpy="0.0 0.0 0.0" xyz="0.0 0.0 0.0"/>
    <parent link="actuated_lidar_front_hokuyo_axis_aligned"/>
    <child link="actuated_lidar_front_hokuyo"/>
  </joint>
  <link name="actuated_lidar_front_hokuyo">
    <visual>
      <origin rpy="0 0 0" xyz="0 0 0"/>
      <geometry>
        <mesh filename="package://actuated_lidar_description_ori/mesh/case_moving.dae" scale=".001 .001 .001"/>
      </geometry>
    </visual>
    <visual>
      <origin rpy="0 0 0" xyz="0 0 0"/>
      <geometry>
        <mesh filename="package://actuated_lidar_description_ori/mesh/hokuyo_utm_30lx.dae"/>
      </geometry>
      <material name="">
        <color rgba="0.72941 0.35686 0.023529 1"/>
      </material>
    </visual>
    <collision>
      <origin rpy="0 0 0" xyz="0.01 0 -0.01"/>
      <geometry>
        <cylinder length="0.12" radius="0.06"/>
      </geometry>
    </collision>
    <inertial>
      <origin rpy="0 0 0" xyz="0.0 0.0 0.0"/>
      <!-- Set the inertial parameters to neglectable values: these effects will be considered on a different rigid body -->
      <mass value="0.001"/>
      <inertia ixx="0.00001" ixy="0.0" ixz="0.0" iyy="0.00001" iyz="0.0" izz="0.00001"/>
      <!--<mass value="0.057654"/>-->
      <!--<inertia iyy="4.2412E-05" ixy="4.9927E-08" iyz="-9.8165E-09" ixx="3.7174E-05" ixz="1.1015E-05" izz="4.167E-05"/>-->
    </inertial>
  </link>
  <!-- Actuated lidar physics simulation -->
  <gazebo reference="actuated_lidar_front_link">
    <mu1>0.9</mu1>
    <mu2>0.9</mu2>
  </gazebo>
  <!-- Actuated lidar hokuyo simulation and driver -->
  <gazebo reference="actuated_lidar_front_hokuyo">
    <sensor name="actuated_lidar_front_hokuyo" type="gpu_ray">
      <pose>0 0 0 0 0 0</pose>
      <visualize>false</visualize>
      <update_rate>40</update_rate>
      <ray>
        <scan>
          <horizontal>
            <samples>1081</samples>
            <resolution>1</resolution>
            <min_angle>-2.356194496154785</min_angle>
            <max_angle>2.356194496154785</max_angle>
          </horizontal>
        </scan>
        <range>
          <min>0.10</min>
          <max>30.0</max>
          <resolution>0.01</resolution>
        </range>
        <noise>
          <type>gaussian</type>
          <!-- Noise parameters based on published spec for Hokuyo laser
                   achieving "+-30mm" accuracy at range < 10m.  A mean of 0.0m and
                   stddev of 0.01m will put 99.7% of samples within 0.03m of the true
                   reading. -->
          <mean>0.0</mean>
          <stddev>0.01</stddev>
        </noise>
      </ray>
      <plugin filename="libgazebo_ros_gpu_laser.so" name="actuated_lidar_front_hokuyo">
        <topicName>/actuated_lidar_front/scan</topicName>
        <frameName>actuated_lidar_front_hokuyo</frameName>
      </plugin>
    </sensor>
  </gazebo>
  <!-- Actuated lidar dynamixel simulation and driver -->
  <gazebo>
    <plugin filename="libdynamixel_gazebo_plugin.so" name="actuated_lidar_front_dynamixel_controller">
      <joint>actuated_lidar_front_dynamixel</joint>
      <command_topic_name>/actuated_lidar_front/dynamixel/controller/command</command_topic_name>
      <state_topic_name>/actuated_lidar_front/dynamixel/controller/state</state_topic_name>
      <set_goal_position_service_name>/actuated_lidar_front/dynamixel/set_goal_position</set_goal_position_service_name>
      <set_angle_limits_service_name>/actuated_lidar_front/dynamixel/set_angle_limits</set_angle_limits_service_name>
      <set_moving_speed_service_name>/actuated_lidar_front/dynamixel/set_moving_speed</set_moving_speed_service_name>
      <joint_state_topic_name>/actuated_lidar_front/dynamixel/joint_state</joint_state_topic_name>
      <default_pos>0</default_pos>
      <default_torque_limit>100</default_torque_limit>
    </plugin>
  </gazebo>
</robot>

