<?xml version="1.0" ?>
<!-- =================================================================================== -->
<!-- |    This document was autogenerated by xacro from /opt/ros/indigo/share/anymal_description/urdf/anymal.urdf.xacro | -->
<!-- |    EDITING THIS FILE BY HAND IS NOT RECOMMENDED                                 | -->
<!-- =================================================================================== -->
<!--Copyright (C) 2014 by Peter Fankhauser                                   -->
<!--pfankhauser@ethz.ch                                                      -->
<!--                                                                         -->
<!--This program is free software; you can redistribute it and/or modify     -->
<!--it under the terms of the Lesser GNU General Public License as published -->
<!--by the Free Software Foundation; either version 3 of the License, or     -->
<!--(at your option) any later version.                                      -->
<!--                                                                         -->
<!--This program is distributed in the hope that it will be useful,          -->
<!--but WITHOUT ANY WARRANTY; without even the implied warranty of           -->
<!--MERCHANTABILITY or FITNESS FOR A PARTICULAR PURPOSE. See the             -->
<!--Lesser GNU General Public License for more details.                      -->
<!--                                                                         -->
<!--You should have received a copy of the Lesser GNU General Public License -->
<!--along with this program. If not, see <http://www.gnu.org/licenses/>.     -->
<!-- Description of the Anymal robot with default configuration. -->
<robot name="anymal" xmlns:xacro="http://www.ros.org/wiki/xacro">
  <!-- Import shared components -->
  <material name="black">
    <color rgba="0.0 0.0 0.0 1.0"/>
  </material>
  <material name="blue">
    <color rgba="0.0 0.0 0.8 1.0"/>
  </material>
  <material name="green">
    <color rgba="0.0 0.8 0.0 1.0"/>
  </material>
  <material name="grey">
    <color rgba="0.2 0.2 0.2 1.0"/>
  </material>
  <material name="light_grey">
    <color rgba="0.4 0.4 0.4 1.0"/>
  </material>
  <material name="orange">
    <color rgba="1.0 0.423529411765 0.0392156862745 1.0"/>
  </material>
  <material name="brown">
    <color rgba="0.870588235294 0.811764705882 0.764705882353 1.0"/>
  </material>
  <material name="red">
    <color rgba="0.8 0.0 0.0 1.0"/>
  </material>
  <material name="white">
    <color rgba="1.0 1.0 1.0 1.0"/>
  </material>
  <!-- Sphere -->
  <!-- Cuboid -->
  <!-- Cylinder -->
  <!-- Import Anymal robot parameters -->
  <!-- Math constants -->
  <!-- Scale factor for mesh -->
  <!-- Contact model -->
  <!-- Values refer to LeftFore leg and will be appropriately reflected to all other legs -->
  <!-- Base/Main body -->
  <!-- [m] -->
  <!-- [m] -->
  <!-- [m] -->
  <!-- [m] -->
  <!-- [m] -->
  <!-- [m] -->
  <!-- [m] -->
  <!-- [m] -->
  <!-- [kg] -->
  <!-- [kg * m^2] -->
  <!-- [kg * m^2] -->
  <!-- [kg * m^2] -->
  <!-- [kg * m^2] -->
  <!-- [kg * m^2] -->
  <!-- [kg * m^2] -->
  <!-- [m] -->
  <!-- [m] -->
  <!-- [m] -->
  <!-- [m] -->
  <!-- [m] -->
  <!-- [m] -->
  <!-- Hip -->
  <!-- [m] -->
  <!-- [m] -->
  <!-- [m] -->
  <!-- [m] -->
  <!-- [m] -->
  <!-- [m] -->
  <!-- [kg] -->
  <!-- [kg * m^2] -->
  <!-- [kg * m^2] -->
  <!-- [kg * m^2] -->
  <!-- [kg * m^2] -->
  <!-- [kg * m^2] -->
  <!-- [kg * m^2] -->
  <!-- [m] -->
  <!-- [m] -->
  <!-- Thigh -->
  <!-- [m] -->
  <!-- [m] -->
  <!-- [m] -->
  <!-- [m] -->
  <!-- [m] -->
  <!-- [m] -->
  <!-- [kg] -->
  <!-- [kg * m^2] -->
  <!-- [kg * m^2] -->
  <!-- [kg * m^2] -->
  <!-- [kg * m^2] -->
  <!-- [kg * m^2] -->
  <!-- [kg * m^2] -->
  <!-- [m] -->
  <!-- [m] -->
  <!-- Shank -->
  <!-- [m] -->
  <!-- [m] -->
  <!-- [m] -->
  <!-- [m] -->
  <!-- [m] -->
  <!-- [m] -->
  <!-- [kg] -->
  <!-- [kg * m^2] -->
  <!-- [kg * m^2] -->
  <!-- [kg * m^2] -->
  <!-- [kg * m^2] -->
  <!-- [kg * m^2] -->
  <!-- [kg * m^2] -->
  <!-- [m] -->
  <!-- Foot mount -->
  <!-- [rad] -->
  <!-- [rad] -->
  <!-- Foot sensor - Optoforce -->
  <!-- [m] -->
  <!-- [m] -->
  <!-- [m] -->
  <!-- [m] -->
  <!-- [m] -->
  <!-- Foot -->
  <!-- Joint HAA -->
  <!-- [rad] -->
  <!-- [rad] -->
  <!-- [rad] -->
  <!-- [rad] -->
  <!-- [rad] -->
  <!-- [rad] -->
  <!-- [rad/s] -->
  <!-- [Nm] -->
  <!-- [Nms/rad] -->
  <!-- [Nm] -->
  <!-- Joint HFE -->
  <!-- [rad] -->
  <!-- [rad] -->
  <!-- [rad] -->
  <!-- [rad] -->
  <!-- [rad] -->
  <!-- [rad] -->
  <!-- [rad/s] -->
  <!-- [Nm] -->
  <!-- [Nms/rad] -->
  <!-- [Nm] -->
  <!-- Joint KFE -->
  <!-- [rad] -->
  <!-- [rad] -->
  <!-- [rad] -->
  <!-- [rad] -->
  <!-- [rad] -->
  <!-- [rad] -->
  <!-- [rad/s] -->
  <!-- [Nm] -->
  <!-- [Nms/rad] -->
  <!-- [Nm] -->
  <!-- Import Anymal robot components -->
  <!-- Useful definitions -->
  <!-- Material for the visual primitives -->
  <material name="anymal_material">
    <color rgba="0.76078431 0.73333333 0.72156863 1.0"/>
  </material>
  <!-- Base -->
  <!-- Hip -->
  <!-- Thigh -->
  <!-- Shank -->
  <!-- Foot mount frame -->
  <!-- Foot sensor - Optoforce -->
  <!-- Foot - contact frame -->
  <!-- XSense Mti -->
  <!-- Parameters -->
  <!-- [m] -->
  <!-- [m] -->
  <!-- [m] -->
  <!-- [kg] -->
  <!-- IMU description -->
  <!-- IMU Gazebo -->
  <!-- Import Anymal Gazebo controller -->
  <gazebo>
    <plugin filename="libanymal_gazebo.so" name="gazebo_ros_control">
      <robotNamespace>anymal</robotNamespace>
      <!-- Currently unused -->
      <robotDescription>quadruped_description</robotDescription>
      <robotBaseLink>base</robotBaseLink>
      <statePublisherRate>400.0</statePublisherRate>
    </plugin>
  </gazebo>
  <!-- Import Anymal instantiation -->
  <!-- Base -->
  <!-- Attach the robot to the world link if requested -->
  <!-- Base link -->
  <link name="base">
    <visual>
      <origin rpy="0 0 0" xyz="0 0 0"/>
      <geometry>
        <mesh filename="package://anymal_description/meshes/anymal_base_1_2.dae" scale="0.001 0.001     0.001"/>
      </geometry>
      <material name="anymal_material"/>
    </visual>
    <collision>
      <!-- Lower Frame -->
      <origin rpy="0 0.0 0" xyz="0 0 -0.1285"/>
      <!-- 0.01 addiditonal offset -->
      <geometry>
        <box size="0.77 0.18 0.03"/>
      </geometry>
    </collision>
    <collision>
      <!-- Main Body -->
      <origin rpy="0 0 0" xyz="0 0 0.0065"/>
      <geometry>
        <box size="0.5 0.18 0.26"/>
      </geometry>
    </collision>
    <collision>
      <!-- Upper Frame -->
      <origin rpy="0 0 0" xyz="0 0 0.1515"/>
      <geometry>
        <box size="0.77 0.18 0.03"/>
      </geometry>
    </collision>
  </link>
  <!-- Dummy base_link added to integrate with Director. mfallon -->
  <joint name="base_link_joint" type="fixed">
    <parent link="base"/>
    <child link="base_link"/>
  </joint>
  <link name="base_link"/>
  <!-- Fixed joint to add dummy inertia link -->
  <joint name="base_to_base_inertia" type="fixed">
    <parent link="base"/>
    <child link="base_inertia"/>
    <origin rpy="0 0 0" xyz="0 0 0"/>
  </joint>
  <!-- Dummy inertia link, because KDL cannot have inertia on the base link -->
  <link name="base_inertia">
    <inertial>
      <origin rpy="0 0 0" xyz="-0.0022 0.0002 0.0132"/>
      <mass value="20.382"/>
      <inertia ixx="0.285499885882" ixy="-0.00043909199137" ixz="0.00991141477838" iyy="0.838202465576" iyz="-0.000542366600469" izz="0.805533312565"/>
    </inertial>
  </link>
  <!-- Left fore components -->
  <!-- Hip link -->
  <link name="LF_HIP">
    <visual>
      <origin rpy="0.0 1.57079632679 0" xyz="0 0 0"/>
      <geometry>
        <mesh filename="package://anymal_description/meshes/anymal_hip.dae" scale="0.001 0.001     0.001"/>
      </geometry>
    </visual>
    <collision>
      <origin rpy="1.57079632679 0 0" xyz="0.0585 -0.01 0.0"/>
      <geometry>
        <cylinder length="0.08" radius="0.04"/>
      </geometry>
    </collision>
    <inertial>
      <origin rpy="0 0 0" xyz="-0.0136 0.0 0.0"/>
      <mass value="1.109"/>
      <inertia ixx="0.000994191042823" ixy="-6.5129363804e-05" ixz="2.401158211e-06" iyy="0.00123419996419" iyz="2.2109968e-08" izz="0.00142289159565"/>
    </inertial>
  </link>
  <!-- Hip joint -->
  <joint name="LF_HAA" type="revolute">
    <parent link="base"/>
    <child link="LF_HIP"/>
    <origin xyz="0.2595                    0.115                    0.0"/>
    <axis xyz="1 0 0"/>
    <limit effort="40" lower="-6.28" upper="6.28" velocity="15"/>
    <dynamics damping="0.0" friction="0.0"/>
  </joint>
  <!-- Thigh link -->
  <link name="LF_THIGH">
    <visual>
      <origin rpy="0 0 0.0" xyz="0 0 0"/>
      <geometry>
        <mesh filename="package://anymal_description/meshes/anymal_thigh.dae" scale="0.001 0.001     0.001"/>
      </geometry>
    </visual>
    <collision>
      <origin rpy="0 0 0" xyz="0 0.02 -0.1"/>
      <geometry>
        <cylinder length="0.2" radius="0.01"/>
      </geometry>
    </collision>
    <collision>
      <origin rpy="1.57079632679 0 0" xyz="0.0 0.03 -0.25"/>
      <geometry>
        <cylinder length="0.08" radius="0.04"/>
      </geometry>
    </collision>
    <inertial>
      <origin rpy="0 0 0" xyz="-0.0001 -0.0001 -0.0001"/>
      <mass value="1.51"/>
      <inertia ixx="0.0110301416624" ixy="-1.65243081e-07" ixz="-1.176910529e-06" iyy="0.0105253146956" iyz="0.00152215719051" izz="0.00163311496798"/>
    </inertial>
  </link>
  <!-- Thigh joint -->
  <joint name="LF_HFE" type="revolute">
    <parent link="LF_HIP"/>
    <child link="LF_THIGH"/>
    <origin xyz="0.0585                    0.0315                    0.0"/>
    <axis xyz="0 1 0"/>
    <limit effort="40" lower="-6.28" upper="6.28" velocity="15"/>
    <dynamics damping="0.0" friction="0.0"/>
  </joint>
  <!-- Shank link -->
  <link name="LF_SHANK">
    <visual>
      <origin rpy="0 0 0" xyz="0 0 0"/>
      <geometry>
        <mesh filename="package://anymal_description/meshes/anymal_shank_2_LF.dae" scale="0.001 0.001     0.001"/>
      </geometry>
    </visual>
    <collision>
      <origin rpy="0 -0.9 0" xyz="0.04 0.03 -0.04"/>
      <geometry>
        <cylinder length="0.13" radius="0.015"/>
      </geometry>
    </collision>
    <collision>
      <origin rpy="-0.2 0.34 0" xyz="0.04 0.01 -0.18"/>
      <geometry>
        <cylinder length="0.19" radius="0.015"/>
      </geometry>
    </collision>
    <inertial>
      <origin rpy="0 0 0" xyz="0.007297066425 -0.007543552828 -0.141776136872"/>
      <mass value="0.361"/>
      <inertia ixx="0.00854654858714" ixy="3.5116124274e-05" ixz="-0.000221415606047" iyy="0.00875231021659" iyz="-0.000434970541796" izz="0.000376183466913"/>
    </inertial>
  </link>
  <!-- Shank joint -->
  <joint name="LF_KFE" type="revolute">
    <parent link="LF_THIGH"/>
    <child link="LF_SHANK"/>
    <origin xyz="0.0 0.111 -0.25"/>
    <axis xyz="0 1 0"/>
    <limit effort="40" lower="-6.28" upper="6.28" velocity="15"/>
    <dynamics damping="0.0" friction="0.0"/>
  </joint>
  <!-- Foot link -->
  <link name="LF_FOOT_MOUNT"/>
  <!-- Foot joint -->
  <joint name="LF_ANKLE_MOUNT" type="fixed">
    <parent link="LF_SHANK"/>
    <child link="LF_FOOT_MOUNT"/>
    <origin rpy="0.323 0.549 0" xyz="0.0 -0.016 -0.31"/>
  </joint>
  <!-- Foot link -->
  <link name="LF_FOOT_SENSOR">
    <collision>
      <origin rpy="0 0 0" xyz="0 0 0"/>
      <geometry>
        <sphere radius="0.025"/>
      </geometry>
    </collision>
  </link>
  <!-- Foot joint -->
  <joint name="LF_MOUNT_TO_SENSOR" type="fixed">
    <parent link="LF_FOOT_MOUNT"/>
    <child link="LF_FOOT_SENSOR"/>
    <origin rpy="0 0 0" xyz="0 0 0"/>
  </joint>
  <!-- Gazebo customization -->
  <gazebo reference="LF_FOOT_SENSOR">
    <kp>1000000.0</kp>
    <kd>100.0</kd>
    <mu1>0.8</mu1>
    <mu2>0.8</mu2>
  </gazebo>
  <gazebo reference="LF_MOUNT_TO_SENSOR"/>
  <!-- Foot link -->
  <link name="LF_FOOT">
    </link>
  <!-- Foot joint -->
  <joint name="LF_SENSOR_TO_FOOT" type="fixed">
    <parent link="LF_FOOT_SENSOR"/>
    <child link="LF_FOOT"/>
    <origin rpy="0 0 0" xyz="0.0 0.0 -0.011"/>
  </joint>
  <!-- Right fore components -->
  <!-- Hip link -->
  <link name="RF_HIP">
    <visual>
      <origin rpy="3.14159265359 -1.57079632679 0" xyz="0 0 0"/>
      <geometry>
        <mesh filename="package://anymal_description/meshes/anymal_hip.dae" scale="0.001 0.001     0.001"/>
      </geometry>
    </visual>
    <collision>
      <origin rpy="1.57079632679 0 0" xyz="0.0585 0.01 0.0"/>
      <geometry>
        <cylinder length="0.08" radius="0.04"/>
      </geometry>
    </collision>
    <inertial>
      <origin rpy="0 0 0" xyz="-0.0136 -0.0 0.0"/>
      <mass value="1.109"/>
      <inertia ixx="0.000994191042823" ixy="6.5129363804e-05" ixz="2.401158211e-06" iyy="0.00123419996419" iyz="2.2109968e-08" izz="0.00142289159565"/>
    </inertial>
  </link>
  <!-- Hip joint -->
  <joint name="RF_HAA" type="revolute">
    <parent link="base"/>
    <child link="RF_HIP"/>
    <origin xyz="0.2595                    -0.115                    0.0"/>
    <axis xyz="1 0 0"/>
    <limit effort="40" lower="-6.28" upper="6.28" velocity="15"/>
    <dynamics damping="0.0" friction="0.0"/>
  </joint>
  <!-- Thigh link -->
  <link name="RF_THIGH">
    <visual>
      <origin rpy="0 0 3.14159265359" xyz="0 0 0"/>
      <geometry>
        <mesh filename="package://anymal_description/meshes/anymal_thigh.dae" scale="0.001 0.001     0.001"/>
      </geometry>
    </visual>
    <collision>
      <origin rpy="0 0 0" xyz="0 -0.02 -0.1"/>
      <geometry>
        <cylinder length="0.2" radius="0.01"/>
      </geometry>
    </collision>
    <collision>
      <origin rpy="1.57079632679 0 0" xyz="0.0 -0.03 -0.25"/>
      <geometry>
        <cylinder length="0.08" radius="0.04"/>
      </geometry>
    </collision>
    <inertial>
      <origin rpy="0 0 0" xyz="-0.0001 0.0001 -0.0001"/>
      <mass value="1.51"/>
      <inertia ixx="0.0110301416624" ixy="-1.65243081e-07" ixz="1.176910529e-06" iyy="0.0105253146956" iyz="-0.00152215719051" izz="0.00163311496798"/>
    </inertial>
  </link>
  <!-- Thigh joint -->
  <joint name="RF_HFE" type="revolute">
    <parent link="RF_HIP"/>
    <child link="RF_THIGH"/>
    <origin xyz="0.0585                    -0.0315                    0.0"/>
    <axis xyz="0 1 0"/>
    <limit effort="40" lower="-6.28" upper="6.28" velocity="15"/>
    <dynamics damping="0.0" friction="0.0"/>
  </joint>
  <!-- Shank link -->
  <link name="RF_SHANK">
    <visual>
      <origin rpy="0 0 0" xyz="0 0 0"/>
      <geometry>
        <mesh filename="package://anymal_description/meshes/anymal_shank_2_RF.dae" scale="0.001 0.001     0.001"/>
      </geometry>
    </visual>
    <collision>
      <origin rpy="0 -0.9 0" xyz="0.04 -0.03 -0.04"/>
      <geometry>
        <cylinder length="0.13" radius="0.015"/>
      </geometry>
    </collision>
    <collision>
      <origin rpy="0.2 0.34 0" xyz="0.04 -0.01 -0.18"/>
      <geometry>
        <cylinder length="0.19" radius="0.015"/>
      </geometry>
    </collision>
    <inertial>
      <origin rpy="0 0 0" xyz="0.007297066425 0.007543552828 -0.141776136872"/>
      <mass value="0.361"/>
      <inertia ixx="0.00854654858714" ixy="-3.5116124274e-05" ixz="-0.000221415606047" iyy="0.00875231021659" iyz="0.000434970541796" izz="0.000376183466913"/>
    </inertial>
  </link>
  <!-- Shank joint -->
  <joint name="RF_KFE" type="revolute">
    <parent link="RF_THIGH"/>
    <child link="RF_SHANK"/>
    <origin xyz="0.0 -0.111 -0.25"/>
    <axis xyz="0 1 0"/>
    <limit effort="40" lower="-6.28" upper="6.28" velocity="15"/>
    <dynamics damping="0.0" friction="0.0"/>
  </joint>
  <!-- Foot link -->
  <link name="RF_FOOT_MOUNT"/>
  <!-- Foot joint -->
  <joint name="RF_ANKLE_MOUNT" type="fixed">
    <parent link="RF_SHANK"/>
    <child link="RF_FOOT_MOUNT"/>
    <origin rpy="-0.323 0.549 0" xyz="0.0 0.016 -0.31"/>
  </joint>
  <!-- Foot link -->
  <link name="RF_FOOT_SENSOR">
    <collision>
      <origin rpy="0 0 0" xyz="0 0 0"/>
      <geometry>
        <sphere radius="0.025"/>
      </geometry>
    </collision>
  </link>
  <!-- Foot joint -->
  <joint name="RF_MOUNT_TO_SENSOR" type="fixed">
    <parent link="RF_FOOT_MOUNT"/>
    <child link="RF_FOOT_SENSOR"/>
    <origin rpy="0 0 0" xyz="0 0 0"/>
  </joint>
  <!-- Gazebo customization -->
  <gazebo reference="RF_FOOT_SENSOR">
    <kp>1000000.0</kp>
    <kd>100.0</kd>
    <mu1>0.8</mu1>
    <mu2>0.8</mu2>
  </gazebo>
  <gazebo reference="RF_MOUNT_TO_SENSOR"/>
  <!-- Foot link -->
  <link name="RF_FOOT">
    </link>
  <!-- Foot joint -->
  <joint name="RF_SENSOR_TO_FOOT" type="fixed">
    <parent link="RF_FOOT_SENSOR"/>
    <child link="RF_FOOT"/>
    <origin rpy="0 0 0" xyz="0.0 0.0 -0.011"/>
  </joint>
  <!-- Left hind components -->
  <!-- Hip link -->
  <link name="LH_HIP">
    <visual>
      <origin rpy="0.0 -1.57079632679 0" xyz="0 0 0"/>
      <geometry>
        <mesh filename="package://anymal_description/meshes/anymal_hip.dae" scale="0.001 0.001     0.001"/>
      </geometry>
    </visual>
    <collision>
      <origin rpy="1.57079632679 0 0" xyz="-0.0585 -0.01 0.0"/>
      <geometry>
        <cylinder length="0.08" radius="0.04"/>
      </geometry>
    </collision>
    <inertial>
      <origin rpy="0 0 0" xyz="0.0136 0.0 0.0"/>
      <mass value="1.109"/>
      <inertia ixx="0.000994191042823" ixy="6.5129363804e-05" ixz="2.401158211e-06" iyy="0.00123419996419" iyz="2.2109968e-08" izz="0.00142289159565"/>
    </inertial>
  </link>
  <!-- Hip joint -->
  <joint name="LH_HAA" type="revolute">
    <parent link="base"/>
    <child link="LH_HIP"/>
    <origin xyz="-0.2595                    0.115                    0.0"/>
    <axis xyz="1 0 0"/>
    <limit effort="40" lower="-6.28" upper="6.28" velocity="15"/>
    <dynamics damping="0.0" friction="0.0"/>
  </joint>
  <!-- Thigh link -->
  <link name="LH_THIGH">
    <visual>
      <origin rpy="0 0 0.0" xyz="0 0 0"/>
      <geometry>
        <mesh filename="package://anymal_description/meshes/anymal_thigh.dae" scale="0.001 0.001     0.001"/>
      </geometry>
    </visual>
    <collision>
      <origin rpy="0 0 0" xyz="0 0.02 -0.1"/>
      <geometry>
        <cylinder length="0.2" radius="0.01"/>
      </geometry>
    </collision>
    <collision>
      <origin rpy="1.57079632679 0 0" xyz="0.0 0.03 -0.25"/>
      <geometry>
        <cylinder length="0.08" radius="0.04"/>
      </geometry>
    </collision>
    <inertial>
      <origin rpy="0 0 0" xyz="0.0001 -0.0001 -0.0001"/>
      <mass value="1.51"/>
      <inertia ixx="0.0110301416624" ixy="-1.65243081e-07" ixz="-1.176910529e-06" iyy="0.0105253146956" iyz="0.00152215719051" izz="0.00163311496798"/>
    </inertial>
  </link>
  <!-- Thigh joint -->
  <joint name="LH_HFE" type="revolute">
    <parent link="LH_HIP"/>
    <child link="LH_THIGH"/>
    <origin xyz="-0.0585                    0.0315                    0.0"/>
    <axis xyz="0 1 0"/>
    <limit effort="40" lower="-6.28" upper="6.28" velocity="15"/>
    <dynamics damping="0.0" friction="0.0"/>
  </joint>
  <!-- Shank link -->
  <link name="LH_SHANK">
    <visual>
      <origin rpy="0 0 0" xyz="0 0 0"/>
      <geometry>
        <mesh filename="package://anymal_description/meshes/anymal_shank_2_LH.dae" scale="0.001 0.001     0.001"/>
      </geometry>
    </visual>
    <collision>
      <origin rpy="0 0.9 0" xyz="-0.04 0.03 -0.04"/>
      <geometry>
        <cylinder length="0.13" radius="0.015"/>
      </geometry>
    </collision>
    <collision>
      <origin rpy="-0.2 -0.34 0" xyz="-0.04 0.01 -0.18"/>
      <geometry>
        <cylinder length="0.19" radius="0.015"/>
      </geometry>
    </collision>
    <inertial>
      <origin rpy="0 0 0" xyz="-0.007297066425 -0.007543552828 -0.141776136872"/>
      <mass value="0.361"/>
      <inertia ixx="0.00854654858714" ixy="-3.5116124274e-05" ixz="0.000221415606047" iyy="0.00875231021659" iyz="-0.000434970541796" izz="0.000376183466913"/>
    </inertial>
  </link>
  <!-- Shank joint -->
  <joint name="LH_KFE" type="revolute">
    <parent link="LH_THIGH"/>
    <child link="LH_SHANK"/>
    <origin xyz="-0.0 0.111 -0.25"/>
    <axis xyz="0 1 0"/>
    <limit effort="40" lower="-6.28" upper="6.28" velocity="15"/>
    <dynamics damping="0.0" friction="0.0"/>
  </joint>
  <!-- Foot link -->
  <link name="LH_FOOT_MOUNT"/>
  <!-- Foot joint -->
  <joint name="LH_ANKLE_MOUNT" type="fixed">
    <parent link="LH_SHANK"/>
    <child link="LH_FOOT_MOUNT"/>
    <origin rpy="0.323 -0.549 0" xyz="-0.0 -0.016 -0.31"/>
  </joint>
  <!-- Foot link -->
  <link name="LH_FOOT_SENSOR">
    <collision>
      <origin rpy="0 0 0" xyz="0 0 0"/>
      <geometry>
        <sphere radius="0.025"/>
      </geometry>
    </collision>
  </link>
  <!-- Foot joint -->
  <joint name="LH_MOUNT_TO_SENSOR" type="fixed">
    <parent link="LH_FOOT_MOUNT"/>
    <child link="LH_FOOT_SENSOR"/>
    <origin rpy="0 0 0" xyz="0 0 0"/>
  </joint>
  <!-- Gazebo customization -->
  <gazebo reference="LH_FOOT_SENSOR">
    <kp>1000000.0</kp>
    <kd>100.0</kd>
    <mu1>0.8</mu1>
    <mu2>0.8</mu2>
  </gazebo>
  <gazebo reference="LH_MOUNT_TO_SENSOR"/>
  <!-- Foot link -->
  <link name="LH_FOOT">
    </link>
  <!-- Foot joint -->
  <joint name="LH_SENSOR_TO_FOOT" type="fixed">
    <parent link="LH_FOOT_SENSOR"/>
    <child link="LH_FOOT"/>
    <origin rpy="0 0 0" xyz="0.0 0.0 -0.011"/>
  </joint>
  <!-- Right hind components -->
  <!-- Hip link -->
  <link name="RH_HIP">
    <visual>
      <origin rpy="3.14159265359 1.57079632679 0" xyz="0 0 0"/>
      <geometry>
        <mesh filename="package://anymal_description/meshes/anymal_hip.dae" scale="0.001 0.001     0.001"/>
      </geometry>
    </visual>
    <collision>
      <origin rpy="1.57079632679 0 0" xyz="-0.0585 0.01 0.0"/>
      <geometry>
        <cylinder length="0.08" radius="0.04"/>
      </geometry>
    </collision>
    <inertial>
      <origin rpy="0 0 0" xyz="0.0136 -0.0 0.0"/>
      <mass value="1.109"/>
      <inertia ixx="0.000994191042823" ixy="-6.5129363804e-05" ixz="2.401158211e-06" iyy="0.00123419996419" iyz="2.2109968e-08" izz="0.00142289159565"/>
    </inertial>
  </link>
  <!-- Hip joint -->
  <joint name="RH_HAA" type="revolute">
    <parent link="base"/>
    <child link="RH_HIP"/>
    <origin xyz="-0.2595                    -0.115                    0.0"/>
    <axis xyz="1 0 0"/>
    <limit effort="40" lower="-6.28" upper="6.28" velocity="15"/>
    <dynamics damping="0.0" friction="0.0"/>
  </joint>
  <!-- Thigh link -->
  <link name="RH_THIGH">
    <visual>
      <origin rpy="0 0 3.14159265359" xyz="0 0 0"/>
      <geometry>
        <mesh filename="package://anymal_description/meshes/anymal_thigh.dae" scale="0.001 0.001     0.001"/>
      </geometry>
    </visual>
    <collision>
      <origin rpy="0 0 0" xyz="0 -0.02 -0.1"/>
      <geometry>
        <cylinder length="0.2" radius="0.01"/>
      </geometry>
    </collision>
    <collision>
      <origin rpy="1.57079632679 0 0" xyz="0.0 -0.03 -0.25"/>
      <geometry>
        <cylinder length="0.08" radius="0.04"/>
      </geometry>
    </collision>
    <inertial>
      <origin rpy="0 0 0" xyz="0.0001 0.0001 -0.0001"/>
      <mass value="1.51"/>
      <inertia ixx="0.0110301416624" ixy="-1.65243081e-07" ixz="1.176910529e-06" iyy="0.0105253146956" iyz="-0.00152215719051" izz="0.00163311496798"/>
    </inertial>
  </link>
  <!-- Thigh joint -->
  <joint name="RH_HFE" type="revolute">
    <parent link="RH_HIP"/>
    <child link="RH_THIGH"/>
    <origin xyz="-0.0585                    -0.0315                    0.0"/>
    <axis xyz="0 1 0"/>
    <limit effort="40" lower="-6.28" upper="6.28" velocity="15"/>
    <dynamics damping="0.0" friction="0.0"/>
  </joint>
  <!-- Shank link -->
  <link name="RH_SHANK">
    <visual>
      <origin rpy="0 0 0" xyz="0 0 0"/>
      <geometry>
        <mesh filename="package://anymal_description/meshes/anymal_shank_2_RH.dae" scale="0.001 0.001     0.001"/>
      </geometry>
    </visual>
    <collision>
      <origin rpy="0 0.9 0" xyz="-0.04 -0.03 -0.04"/>
      <geometry>
        <cylinder length="0.13" radius="0.015"/>
      </geometry>
    </collision>
    <collision>
      <origin rpy="0.2 -0.34 0" xyz="-0.04 -0.01 -0.18"/>
      <geometry>
        <cylinder length="0.19" radius="0.015"/>
      </geometry>
    </collision>
    <inertial>
      <origin rpy="0 0 0" xyz="-0.007297066425 0.007543552828 -0.141776136872"/>
      <mass value="0.361"/>
      <inertia ixx="0.00854654858714" ixy="3.5116124274e-05" ixz="0.000221415606047" iyy="0.00875231021659" iyz="0.000434970541796" izz="0.000376183466913"/>
    </inertial>
  </link>
  <!-- Shank joint -->
  <joint name="RH_KFE" type="revolute">
    <parent link="RH_THIGH"/>
    <child link="RH_SHANK"/>
    <origin xyz="-0.0 -0.111 -0.25"/>
    <axis xyz="0 1 0"/>
    <limit effort="40" lower="-6.28" upper="6.28" velocity="15"/>
    <dynamics damping="0.0" friction="0.0"/>
  </joint>
  <!-- Foot link -->
  <link name="RH_FOOT_MOUNT"/>
  <!-- Foot joint -->
  <joint name="RH_ANKLE_MOUNT" type="fixed">
    <parent link="RH_SHANK"/>
    <child link="RH_FOOT_MOUNT"/>
    <origin rpy="-0.323 -0.549 0" xyz="-0.0 0.016 -0.31"/>
  </joint>
  <!-- Foot link -->
  <link name="RH_FOOT_SENSOR">
    <collision>
      <origin rpy="0 0 0" xyz="0 0 0"/>
      <geometry>
        <sphere radius="0.025"/>
      </geometry>
    </collision>
  </link>
  <!-- Foot joint -->
  <joint name="RH_MOUNT_TO_SENSOR" type="fixed">
    <parent link="RH_FOOT_MOUNT"/>
    <child link="RH_FOOT_SENSOR"/>
    <origin rpy="0 0 0" xyz="0 0 0"/>
  </joint>
  <!-- Gazebo customization -->
  <gazebo reference="RH_FOOT_SENSOR">
    <kp>1000000.0</kp>
    <kd>100.0</kd>
    <mu1>0.8</mu1>
    <mu2>0.8</mu2>
  </gazebo>
  <gazebo reference="RH_MOUNT_TO_SENSOR"/>
  <!-- Foot link -->
  <link name="RH_FOOT">
    </link>
  <!-- Foot joint -->
  <joint name="RH_SENSOR_TO_FOOT" type="fixed">
    <parent link="RH_FOOT_SENSOR"/>
    <child link="RH_FOOT"/>
    <origin rpy="0 0 0" xyz="0.0 0.0 -0.011"/>
  </joint>
  <!-- Xsens Mti -->
  <!-- update_rate is not used -> Could be removed -->
  <link name="imu_link">
    <visual>
      <origin rpy="0 0 0" xyz="0 0 0.011"/>
      <geometry>
        <box size="0.058 0.058 0.022"/>
      </geometry>
      <material name="orange"/>
    </visual>
    <collision>
      <origin rpy="0 0 0" xyz="0 0 0.011"/>
      <geometry>
        <box size="0.058 0.058 0.022"/>
      </geometry>
    </collision>
    <inertial>
      <mass value="0.05"/>
      <origin xyz="0 0 0"/>
      <inertia ixx="1.60333333333e-05" ixy="0.0" ixz="0.0" iyy="2.80333333333e-05" iyz="0.0" izz="1.60333333333e-05"/>
    </inertial>
  </link>
  <joint name="imu_joint" type="fixed">
    <parent link="base"/>
    <child link="imu_link"/>
    <origin rpy="0 0 3.14159265359" xyz="-0.0959 -0.0060 -0.0055"/>
  </joint>
  <gazebo reference="imu_link">
    <material>Gazebo/Orange</material>
    <mu1>0.8</mu1>
    <mu2>0.8</mu2>
  </gazebo>
  <gazebo reference="imu_joint">
      </gazebo>
  <gazebo>
    <plugin filename="libhector_gazebo_ros_imu.so" name="imu_plugin">
      <robotNamespace>sensors</robotNamespace>
      <bodyName>imu_link</bodyName>
      <frameId>/imu_link</frameId>
      <topicName>imu</topicName>
      <biasTopicName>imu/bias</biasTopicName>
      <serviceName>imu/calibrate</serviceName>
    </plugin>
  </gazebo>
</robot>



